Traceback (most recent call last):
Traceback (most recent call last):
  File "/opt/anaconda3/lib/python3.9/site-packages/gitdb/util.py", line 323, in open
  File "/opt/anaconda3/lib/python3.9/site-packages/gitdb/util.py", line 323, in open
    fd = os.open(self._lockfilepath(), lockmode, int("600", 8))
    fd = os.open(self._lockfilepath(), lockmode, int("600", 8))
FileExistsError: [Errno 17] File exists: '/Users/riddhi/Library/CloudStorage/OneDrive-Nexus365/Oxford/Research Projects/Ox_AgencyParadox/1_Data&Analysis/Models/agency_pymdp/.git/index.lock'

The above exception was the direct cause of the following exception:

FileExistsError: [Errno 17] File exists: '/Users/riddhi/Library/CloudStorage/OneDrive-Nexus365/Oxford/Research Projects/Ox_AgencyParadox/1_Data&Analysis/Models/agency_pymdp/.git/index.lock'
Traceback (most recent call last):

The above exception was the direct cause of the following exception:

  File "/Users/riddhi/Library/CloudStorage/OneDrive-Nexus365/Oxford/Research Projects/Ox_AgencyParadox/1_Data&Analysis/Models/agency_pymdp/run_experiment.py", line 166, in <module>
Traceback (most recent call last):
  File "/Users/riddhi/Library/CloudStorage/OneDrive-Nexus365/Oxford/Research Projects/Ox_AgencyParadox/1_Data&Analysis/Models/agency_pymdp/run_experiment.py", line 166, in <module>
    experiment_dir, git_hash = setup_log_dir(data_dir, file_name)
  File "/Users/riddhi/Library/CloudStorage/OneDrive-Nexus365/Oxford/Research Projects/Ox_AgencyParadox/1_Data&Analysis/Models/agency_pymdp/run_experiment.py", line 38, in setup_log_dir
    experiment_dir, git_hash = setup_log_dir(data_dir, file_name)
  File "/Users/riddhi/Library/CloudStorage/OneDrive-Nexus365/Oxford/Research Projects/Ox_AgencyParadox/1_Data&Analysis/Models/agency_pymdp/run_experiment.py", line 38, in setup_log_dir
    git_repo.index.add(changed_files)
  File "/opt/anaconda3/lib/python3.9/site-packages/git/index/base.py", line 872, in add
    git_repo.index.add(changed_files)
  File "/opt/anaconda3/lib/python3.9/site-packages/git/index/base.py", line 872, in add
    self.write(ignore_extension_data=not write_extension_data)
    self.write(ignore_extension_data=not write_extension_data)
  File "/opt/anaconda3/lib/python3.9/site-packages/git/index/base.py", line 225, in write
  File "/opt/anaconda3/lib/python3.9/site-packages/git/index/base.py", line 225, in write
    stream = lfd.open(write=True, stream=True)
  File "/opt/anaconda3/lib/python3.9/site-packages/gitdb/util.py", line 330, in open
    stream = lfd.open(write=True, stream=True)
  File "/opt/anaconda3/lib/python3.9/site-packages/gitdb/util.py", line 330, in open
    raise OSError("Lock at %r could not be obtained" % self._lockfilepath()) from e
OSError: Lock at '/Users/riddhi/Library/CloudStorage/OneDrive-Nexus365/Oxford/Research Projects/Ox_AgencyParadox/1_Data&Analysis/Models/agency_pymdp/.git/index.lock' could not be obtained
    raise OSError("Lock at %r could not be obtained" % self._lockfilepath()) from e
OSError: Lock at '/Users/riddhi/Library/CloudStorage/OneDrive-Nexus365/Oxford/Research Projects/Ox_AgencyParadox/1_Data&Analysis/Models/agency_pymdp/.git/index.lock' could not be obtained
Traceback (most recent call last):
  File "/opt/anaconda3/lib/python3.9/site-packages/gitdb/util.py", line 323, in open
    fd = os.open(self._lockfilepath(), lockmode, int("600", 8))
FileExistsError: [Errno 17] File exists: '/Users/riddhi/Library/CloudStorage/OneDrive-Nexus365/Oxford/Research Projects/Ox_AgencyParadox/1_Data&Analysis/Models/agency_pymdp/.git/refs/heads/experiments.lock'

The above exception was the direct cause of the following exception:

Traceback (most recent call last):
  File "/Users/riddhi/Library/CloudStorage/OneDrive-Nexus365/Oxford/Research Projects/Ox_AgencyParadox/1_Data&Analysis/Models/agency_pymdp/run_experiment.py", line 166, in <module>
    experiment_dir, git_hash = setup_log_dir(data_dir, file_name)
  File "/Users/riddhi/Library/CloudStorage/OneDrive-Nexus365/Oxford/Research Projects/Ox_AgencyParadox/1_Data&Analysis/Models/agency_pymdp/run_experiment.py", line 39, in setup_log_dir
    git_repo.index.commit(f"Experiment {current_time_str}")
  File "/opt/anaconda3/lib/python3.9/site-packages/git/index/base.py", line 1050, in commit
    rval = Commit.create_from_tree(
  File "/opt/anaconda3/lib/python3.9/site-packages/git/objects/commit.py", line 613, in create_from_tree
    repo.head.set_commit(new_commit, logmsg=message)
  File "/opt/anaconda3/lib/python3.9/site-packages/git/refs/symbolic.py", line 313, in set_commit
    self.set_object(commit, logmsg)
  File "/opt/anaconda3/lib/python3.9/site-packages/git/refs/symbolic.py", line 346, in set_object
    return self._get_reference().set_object(object, logmsg)
  File "/opt/anaconda3/lib/python3.9/site-packages/git/refs/reference.py", line 86, in set_object
    super(Reference, self).set_object(object, logmsg)
  File "/opt/anaconda3/lib/python3.9/site-packages/git/refs/symbolic.py", line 343, in set_object
    return self.set_reference(object, logmsg)
  File "/opt/anaconda3/lib/python3.9/site-packages/git/refs/symbolic.py", line 418, in set_reference
    fd = lfd.open(write=True, stream=True)
  File "/opt/anaconda3/lib/python3.9/site-packages/gitdb/util.py", line 330, in open
    raise OSError("Lock at %r could not be obtained" % self._lockfilepath()) from e
OSError: Lock at '/Users/riddhi/Library/CloudStorage/OneDrive-Nexus365/Oxford/Research Projects/Ox_AgencyParadox/1_Data&Analysis/Models/agency_pymdp/.git/refs/heads/experiments.lock' could not be obtained
